Failure # 1 (occurred at 2025-02-01_17-47-34)
[36mray::ImplicitFunc.train()[39m (pid=4240, ip=127.0.0.1, actor_id=dba41df8d6f6fe3420ac76b701000000, repr=train_func)
  File "python\ray\_raylet.pyx", line 1883, in ray._raylet.execute_task
  File "python\ray\_raylet.pyx", line 1824, in ray._raylet.execute_task.function_executor
  File "c:\Users\Kone\ftllm\yes\Lib\site-packages\ray\_private\function_manager.py", line 696, in actor_method_executor
    return method(__ray_actor, *args, **kwargs)
           ^^^^^^^^^^^^^^^^^^^^^^^^^^^^^^^^^^^^
  File "c:\Users\Kone\ftllm\yes\Lib\site-packages\ray\util\tracing\tracing_helper.py", line 463, in _resume_span
    return method(self, *_args, **_kwargs)
           ^^^^^^^^^^^^^^^^^^^^^^^^^^^^^^^
  File "c:\Users\Kone\ftllm\yes\Lib\site-packages\ray\tune\trainable\trainable.py", line 331, in train
    raise skipped from exception_cause(skipped)
  File "c:\Users\Kone\ftllm\yes\Lib\site-packages\ray\air\_internal\util.py", line 107, in run
    self._ret = self._target(*self._args, **self._kwargs)
                ^^^^^^^^^^^^^^^^^^^^^^^^^^^^^^^^^^^^^^^^^
  File "c:\Users\Kone\ftllm\yes\Lib\site-packages\ray\tune\trainable\function_trainable.py", line 44, in <lambda>
    training_func=lambda: self._trainable_func(self.config),
                          ^^^^^^^^^^^^^^^^^^^^^^^^^^^^^^^^^
  File "c:\Users\Kone\ftllm\yes\Lib\site-packages\ray\util\tracing\tracing_helper.py", line 463, in _resume_span
    return method(self, *_args, **_kwargs)
           ^^^^^^^^^^^^^^^^^^^^^^^^^^^^^^^
  File "c:\Users\Kone\ftllm\yes\Lib\site-packages\ray\tune\trainable\function_trainable.py", line 249, in _trainable_func
    output = fn()
             ^^^^
  File "C:\Users\Kone\AppData\Local\Temp\ipykernel_26324\326217947.py", line 118, in train_func
  File "c:\Users\Kone\ftllm\yes\Lib\site-packages\transformers\trainer.py", line 2171, in train
    return inner_training_loop(
           ^^^^^^^^^^^^^^^^^^^^
  File "c:\Users\Kone\ftllm\yes\Lib\site-packages\transformers\trainer.py", line 2598, in _inner_training_loop
    self._maybe_log_save_evaluate(
  File "c:\Users\Kone\ftllm\yes\Lib\site-packages\transformers\trainer.py", line 3071, in _maybe_log_save_evaluate
    metrics = self._evaluate(trial, ignore_keys_for_eval)
              ^^^^^^^^^^^^^^^^^^^^^^^^^^^^^^^^^^^^^^^^^^^
  File "c:\Users\Kone\ftllm\yes\Lib\site-packages\transformers\trainer.py", line 3025, in _evaluate
    metrics = self.evaluate(ignore_keys=ignore_keys_for_eval)
              ^^^^^^^^^^^^^^^^^^^^^^^^^^^^^^^^^^^^^^^^^^^^^^^
  File "C:\Users\Kone\AppData\Local\Temp\ipykernel_26324\326217947.py", line 43, in evaluate
  File "C:\Users\Kone\AppData\Local\Temp\ipykernel_26324\326217947.py", line 39, in _report_to_ray
  File "c:\Users\Kone\ftllm\yes\Lib\site-packages\ray\train\_internal\session.py", line 663, in wrapper
    return fn(*args, **kwargs)
           ^^^^^^^^^^^^^^^^^^^
  File "c:\Users\Kone\ftllm\yes\Lib\site-packages\ray\tune\trainable\trainable_fn_utils.py", line 44, in report
    get_session().report(metrics, checkpoint=checkpoint)
  File "c:\Users\Kone\ftllm\yes\Lib\site-packages\ray\train\_internal\session.py", line 422, in report
    metrics = self._auto_fill_metrics(metrics)
              ^^^^^^^^^^^^^^^^^^^^^^^^^^^^^^^^
  File "c:\Users\Kone\ftllm\yes\Lib\site-packages\ray\train\_internal\session.py", line 332, in _auto_fill_metrics
    if TIME_THIS_ITER_S in result:
       ^^^^^^^^^^^^^^^^^^^^^^^^^^
TypeError: argument of type 'float' is not iterable
